<?xml version="1.0" ?>
<!-- =================================================================================== -->
<!-- |    This document was autogenerated by xacro from /home/jian/桌面/ur5_robotiq_2f_85/src/ur_gazebo/urdf/ur5_gripper.xacro | -->
<!-- |    EDITING THIS FILE BY HAND IS NOT RECOMMENDED                                 | -->
<!-- =================================================================================== -->
<robot name="ur5_gripper">
    <gazebo>
        <plugin filename="libgazebo_ros_control.so" name="ros_control">
            <!--robotNamespace>/</robotNamespace-->
            <!--robotSimType>gazebo_ros_control/DefaultRobotHWSim</robotSimType-->
        </plugin>
        <plugin name="gazebo_ros_control">
            <robotNamespace>/</robotNamespace>
        </plugin>
    </gazebo>
    <!--joint_limited="true"
    shoulder_pan_lower_limit="${-pi}" shoulder_pan_upper_limit="${pi}"
    shoulder_lift_lower_limit="${-pi}" shoulder_lift_upper_limit="${pi}"
    elbow_joint_lower_limit="${-pi}" elbow_joint_upper_limit="${pi}"
    wrist_1_lower_limit="${-pi}" wrist_1_upper_limit="${pi}"
    wrist_2_lower_limit="${-pi}" wrist_2_upper_limit="${pi}"
    wrist_3_lower_limit="${-pi}" wrist_3_upper_limit="${pi}"
    transmission_hw_interface="$(arg transmission_hw_interface)"-->
    <link name="world" />
    <joint name="world_joint" type="fixed">
        <parent link="world" />
        <child link="base_link" />
        <origin rpy="0.0 0.0 0.0" xyz="0.0 0.0 0.75" />
    </joint>
    <link name="base_link">
        <!-- 机械臂基座 -->
        <visual>
            <geometry>
                <mesh filename="package://ur_gazebo/mesh/visual/base.dae" />
            </geometry>
            <material name="LightGrey">
                <color rgba="0.7 0.7 0.7 1.0" />
            </material>
        </visual>
        <collision>
            <!-- 碰撞检测 -->
            <geometry>
                <mesh filename="package://ur_gazebo/mesh/collision/base.stl" />
            </geometry>
        </collision>
        <inertial>
            <mass value="4.0" />
            <!-- <xacro:insert_block name="origin" /> -->
            <inertia ixx="0.00443333156" ixy="0.0" ixz="0.0" iyy="0.00443333156" iyz="0.0" izz="0.0072" />
            <origin xyz="0 0 0" rpy="0 0 0" />
        </inertial>
    </link>
    <!-- 机械臂第一个关节自由度 -->
    <joint name="shoulder_pan_joint" type="revolute">
        <parent link="base_link" />
        <child link="shoulder_link" />
        <origin rpy="0.0 0.0 0.0" xyz="0.0 0.0 0.089159" />
        <axis xyz="0 0 1" />
        <!-- z轴为转动轴 -->
        <limit effort="150.0" lower="-3.141592653589793" upper="3.141592653589793" velocity="3.15" />
        <dynamics damping="0.0" friction="0.0" />
    </joint>
    <transmission name="shoulder_pan_trans">
        <type>transmission_interface/SimpleTransmission</type>
        <joint name="shoulder_pan_joint">
            <hardwareInterface>hardware_interface/PositionJointInterface</hardwareInterface>
        </joint>
        <actuator name="shoulder_pan_motor">
            <mechanicalReduction>1</mechanicalReduction>
            <hardwareInterface>hardware_interface/EffortJointInterface</hardwareInterface>
        </actuator>
    </transmission>
    <!-- 第一个连杆 -->
    <link name="shoulder_link">
        <visual>
            <geometry>
                <mesh filename="package://ur_gazebo/mesh/visual/shoulder.dae" />
            </geometry>
            <material name="LightGrey">
                <color rgba="0.7 0.7 0.7 1.0" />
            </material>
        </visual>
        <collision>
            <geometry>
                <mesh filename="package://ur_gazebo/mesh/collision/shoulder.stl" />
            </geometry>
        </collision>
        <inertial>
            <mass value="3.7" />
            <!-- <xacro:insert_block name="origin" /> -->
            <inertia ixx="0.010267495893" ixy="0.0" ixz="0.0" iyy="0.010267495893" iyz="0.0" izz="0.00666" />
            <origin xyz="0 0 0" rpy="0 0 0" />
        </inertial>
    </link>
    <gazebo reference="shoulder_link">
        <selfCollide>true</selfCollide>
    </gazebo>
    <!-- 机械臂第二个关节轴 -->
    <joint name="shoulder_lift_joint" type="revolute">
        <parent link="shoulder_link" />
        <child link="upper_arm_link" />
        <origin rpy="0.0 1.5707963267948966 0.0" xyz="0.0 0.13585 0.0" />
        <axis xyz="0 1 0" />
        <limit effort="150.0" lower="-3.141592653589793" upper="3.141592653589793" velocity="3.15" />
        <dynamics damping="0.0" friction="0.0" />
    </joint>
    <transmission name="shoulder_lift_trans">
        <type>transmission_interface/SimpleTransmission</type>
        <joint name="shoulder_lift_joint">
            <hardwareInterface>hardware_interface/PositionJointInterface</hardwareInterface>
        </joint>
        <actuator name="shoulder_lift_motor">
            <mechanicalReduction>1</mechanicalReduction>
            <hardwareInterface>hardware_interface/EffortJointInterface</hardwareInterface>
        </actuator>
    </transmission>
    <!-- 第二个连杆 -->
    <link name="upper_arm_link">
        <visual>
            <geometry>
                <mesh filename="package://ur_gazebo/mesh/visual/upperarm.dae" />
            </geometry>
            <material name="LightGrey">
                <color rgba="0.7 0.7 0.7 1.0" />
            </material>
        </visual>
        <collision>
            <geometry>
                <mesh filename="package://ur_gazebo/mesh/collision/upperarm.stl" />
            </geometry>
        </collision>
        <inertial>
            <mass value="8.393" />
            <!-- <xacro:insert_block name="origin" /> -->
            <inertia ixx="0.22689067591036005" ixy="0.0" ixz="0.0" iyy="0.22689067591036005" iyz="0.0" izz="0.0151074" />
            <origin xyz="0 0 0" rpy="0 0 0" />
        </inertial>
    </link>
    <gazebo reference="upper_arm_link">
        <selfCollide>true</selfCollide>
    </gazebo>
    <joint name="elbow_joint" type="revolute">
        <parent link="upper_arm_link" />
        <child link="forearm_link" />
        <origin rpy="0.0 0.0 0.0" xyz="0.0 -0.1197 0.425" />
        <axis xyz="0 1 0" />
        <limit effort="150.0" lower="-3.141592653589793" upper="3.141592653589793" velocity="3.15" />
        <dynamics damping="0.0" friction="0.0" />
    </joint>
    <transmission name="elbow_trans">
        <type>transmission_interface/SimpleTransmission</type>
        <joint name="elbow_joint">
            <hardwareInterface>hardware_interface/PositionJointInterface</hardwareInterface>
        </joint>
        <actuator name="elbow_motor">
            <mechanicalReduction>1</mechanicalReduction>
            <hardwareInterface>hardware_interface/EffortJointInterface</hardwareInterface>
        </actuator>
    </transmission>
    <link name="forearm_link">
        <visual>
            <geometry>
                <mesh filename="package://ur_gazebo/mesh/visual/forearm.dae" />
            </geometry>
            <material name="LightGrey">
                <color rgba="0.7 0.7 0.7 1.0" />
            </material>
        </visual>
        <collision>
            <geometry>
                <mesh filename="package://ur_gazebo/mesh/collision/forearm.stl" />
            </geometry>
        </collision>
        <inertial>
            <mass value="2.275" />
            <!-- <xacro:insert_block name="origin" /> -->
            <inertia ixx="0.03121679102890359" ixy="0.0" ixz="0.0" iyy="0.03121679102890359" iyz="0.0" izz="0.004095" />
            <origin xyz="0 0 0" rpy="0 0 0" />
        </inertial>
    </link>
    <gazebo reference="forearm_link">
        <selfCollide>true</selfCollide>
    </gazebo>
    <joint name="wrist_1_joint" type="revolute">
        <parent link="forearm_link" />
        <child link="wrist_1_link" />
        <origin rpy="0.0 1.5707963267948966 0.0" xyz="0.0 0.0 0.39225" />
        <axis xyz="0 1 0" />
        <limit effort="28.0" lower="-3.141592653589793" upper="3.141592653589793" velocity="3.2" />
        <dynamics damping="0.0" friction="0.0" />
    </joint>
    <transmission name="wrist_1_trans">
        <type>transmission_interface/SimpleTransmission</type>
        <joint name="wrist_1_joint">
            <hardwareInterface>hardware_interface/PositionJointInterface</hardwareInterface>
        </joint>
        <actuator name="wrist_1_motor">
            <mechanicalReduction>1</mechanicalReduction>
            <hardwareInterface>hardware_interface/EffortJointInterface</hardwareInterface>
        </actuator>
    </transmission>
    <link name="wrist_1_link">
        <visual>
            <geometry>
                <mesh filename="package://ur_gazebo/mesh/visual/wrist1.dae" />
            </geometry>
            <material name="LightGrey">
                <color rgba="0.7 0.7 0.7 1.0" />
            </material>
        </visual>
        <collision>
            <geometry>
                <mesh filename="package://ur_gazebo/mesh/collision/wrist1.stl" />
            </geometry>
        </collision>
        <inertial>
            <mass value="1.219" />
            <!-- <xacro:insert_block name="origin" /> -->
            <inertia ixx="0.0025598989760400002" ixy="0.0" ixz="0.0" iyy="0.0025598989760400002" iyz="0.0" izz="0.0021942" />
            <origin xyz="0 0 0" rpy="0 0 0" />
        </inertial>
    </link>
    <gazebo reference="wrist_1_link">
        <selfCollide>true</selfCollide>
    </gazebo>
    <!-- ******************************************************************************************************** -->
    <joint name="wrist_2_joint" type="revolute">
        <parent link="wrist_1_link" />
        <child link="wrist_2_link" />
        <origin rpy="0.0 0.0 0.0" xyz="0.0 0.093 0.0" />
        <axis xyz="0 0 1" />
        <limit effort="28.0" lower="-3.141592653589793" upper="3.141592653589793" velocity="3.2" />
        <dynamics damping="0.0" friction="0.0" />
    </joint>
    <transmission name="wrist_2_trans">
        <type>transmission_interface/SimpleTransmission</type>
        <joint name="wrist_2_joint">
            <hardwareInterface>hardware_interface/PositionJointInterface</hardwareInterface>
        </joint>
        <actuator name="wrist_2_motor">
            <mechanicalReduction>1</mechanicalReduction>
            <hardwareInterface>hardware_interface/EffortJointInterface</hardwareInterface>
        </actuator>
    </transmission>
    <link name="wrist_2_link">
        <visual>
            <geometry>
                <mesh filename="package://ur_gazebo/mesh/visual/wrist2.dae" />
            </geometry>
            <material name="LightGrey">
                <color rgba="0.7 0.7 0.7 1.0" />
            </material>
        </visual>
        <collision>
            <geometry>
                <mesh filename="package://ur_gazebo/mesh/collision/wrist2.stl" />
            </geometry>
        </collision>
        <inertial>
            <mass value="1.219" />
            <!-- <xacro:insert_block name="origin" /> -->
            <inertia ixx="0.0025598989760400002" ixy="0.0" ixz="0.0" iyy="0.0025598989760400002" iyz="0.0" izz="0.0021942" />
            <origin xyz="0 0 0" rpy="0 0 0" />
        </inertial>
    </link>
    <gazebo reference="wrist_2_link">
        <selfCollide>true</selfCollide>
    </gazebo>
    <joint name="wrist_3_joint" type="revolute">
        <parent link="wrist_2_link" />
        <child link="wrist_3_link" />
        <origin rpy="0.0 0.0 0.0" xyz="0.0 0.0 0.09465" />
        <axis xyz="0 1 0" />
        <limit effort="28.0" lower="-3.141592653589793" upper="3.141592653589793" velocity="3.2" />
        <dynamics damping="0.0" friction="0.0" />
    </joint>
    <transmission name="wrist_3_trans">
        <type>transmission_interface/SimpleTransmission</type>
        <joint name="wrist_3_joint">
            <hardwareInterface>hardware_interface/PositionJointInterface</hardwareInterface>
        </joint>
        <actuator name="wrist_3_motor">
            <mechanicalReduction>1</mechanicalReduction>
            <hardwareInterface>hardware_interface/EffortJointInterface</hardwareInterface>
        </actuator>
    </transmission>
    <link name="wrist_3_link">
        <visual>
            <geometry>
                <mesh filename="package://ur_gazebo/mesh/visual/wrist3.dae" />
            </geometry>
            <material name="LightGrey">
                <color rgba="0.7 0.7 0.7 1.0" />
            </material>
        </visual>
        <collision>
            <geometry>
                <mesh filename="package://ur_gazebo/mesh/collision/wrist3.stl" />
            </geometry>
        </collision>
        <inertial>
            <mass value="0.1879" />
            <!-- <xacro:insert_block name="origin" /> -->
            <inertia ixx="8.469589112163e-05" ixy="0.0" ixz="0.0" iyy="8.469589112163e-05" iyz="0.0" izz="0.0001321171875" />
            <origin xyz="0 0 0" rpy="0 0 0" />
        </inertial>
    </link>
    <gazebo reference="wrist_3_link">
        <selfCollide>true</selfCollide>
    </gazebo>
    <!--**************************************************-->
    <joint name="ee_fixed_joint" type="fixed">
        <parent link="wrist_3_link" />
        <child link="ee_link" />
        <!--origin xyz="0.0 ${wrist_3_length+0.155} 0.0" rpy="0.0 0.0 ${pi/2.0}" /-->
        <origin rpy="-1.5707963267948966 0  0" xyz="0.0 0.2243 0.0" />
    </joint>
    <!--link name="ee_link">
      <collision>
        <geometry>
          <box size="0.01 0.01 0.01"/>
        </geometry>
        <origin rpy="0 0 0" xyz="-0.01 0 0"/>
      </collision>
    </link-->
    <link name="ee_link" />
    <joint name="wrist_3_link-tool0_fixed_joint" type="fixed">
        <origin rpy="-1.5707963267948966 0 0" xyz="0 0.0823 0" />
        <parent link="wrist_3_link" />
        <child link="tool0" />
    </joint>
    <link name="tool0" />
    <!--**************************************************-->
    <joint name="gripper_base_joint" type="fixed">
        <parent link="tool0" />
        <child link="gripper_base_link" />
        <origin rpy="0 -1.5707963267948966 0" xyz="0 0 0" />
        <!-- <xacro:insert_block name="origin"/> -->
    </joint>
    <link name="gripper_base_link">
        <visual>
            <geometry>
                <mesh filename="package://ur_gazebo/mesh/visual/robotiq_85_base_link.dae" />
            </geometry>
        </visual>
        <collision>
            <geometry>
                <mesh filename="package://ur_gazebo/mesh/collision/robotiq_85_base_link.stl" />
            </geometry>
        </collision>
        <inertial>
            <mass value="0.636951" />
            <origin xyz="0.0 0.0 0.0" rpy="0 0 0" />
            <inertia ixx="0.000380" ixy="0.000000" ixz="0.000000" iyx="0.000000" iyy="0.001110" iyz="0.000000" izx="0.000000" izy="0.000000" izz="0.001171" />
        </inertial>
    </link>
    <gazebo reference="gripper_base_link">
        <implicitSpringDamper>1</implicitSpringDamper>
        <mu1>100000</mu1>
        <mu2>100000</mu2>
        <kp>100000000.0</kp>
        <kd>1.0</kd>
    </gazebo>
    <joint name="gripper_finger1_joint" type="revolute">
        <parent link="gripper_base_link" />
        <child link="gripper_finger1_knuckle_link" />
        <axis xyz="0 0 1" />
        <origin rpy="3.141592653589793 0.0 0.0" xyz="0.05490451627 0.03060114443 0.0" />
        <limit effort="1000" lower="0.0" upper="0.804" velocity="2.0" />
    </joint>
    <joint name="gripper_finger2_joint" type="revolute">
        <parent link="gripper_base_link" />
        <child link="gripper_finger2_knuckle_link" />
        <axis xyz="0 0 1" />
        <origin rpy="0.0 0.0 0.0" xyz="0.05490451627 -0.03060114443 0.0" />
        <limit effort="1000" lower="-3.14" upper="3.14" velocity="100.0" />
        <mimic joint="gripper_finger1_joint" />
    </joint>
    <!--============================================================================-->
    <link name="gripper_finger1_knuckle_link">
        <visual>
            <geometry>
                <mesh filename="package://ur_gazebo/mesh/visual/robotiq_85_knuckle_link.dae" />
            </geometry>
        </visual>
        <collision>
            <geometry>
                <mesh filename="package://ur_gazebo/mesh/collision/robotiq_85_knuckle_link.stl" />
            </geometry>
        </collision>
        <inertial>
            <mass value="0.018491" />
            <origin xyz="0.0 0.0 0.0" rpy="0 0 0" />
            <inertia ixx="0.000009" ixy="-0.000001" ixz="0.000000" iyx="-0.000001" iyy="0.000001" iyz="0.000000" izx="0.000000" izy="0.000000" izz="0.000010" />
        </inertial>
    </link>
    <gazebo reference="gripper_finger1_knuckle_link">
        <implicitSpringDamper>1</implicitSpringDamper>
        <mu1>100000</mu1>
        <mu2>100000</mu2>
        <kp>100000000.0</kp>
        <kd>1.0</kd>
    </gazebo>
    <link name="gripper_finger2_knuckle_link">
        <visual>
            <geometry>
                <mesh filename="package://ur_gazebo/mesh/visual/robotiq_85_knuckle_link.dae" />
            </geometry>
        </visual>
        <collision>
            <geometry>
                <mesh filename="package://ur_gazebo/mesh/collision/robotiq_85_knuckle_link.stl" />
            </geometry>
        </collision>
        <inertial>
            <mass value="0.018491" />
            <origin xyz="0.0 0.0 0.0" rpy="0 0 0" />
            <inertia ixx="0.000009" ixy="-0.000001" ixz="0.000000" iyx="-0.000001" iyy="0.000001" iyz="0.000000" izx="0.000000" izy="0.000000" izz="0.000010" />
        </inertial>
    </link>
    <gazebo reference="gripper_finger2_knuckle_link">
        <implicitSpringDamper>1</implicitSpringDamper>
        <mu1>100000</mu1>
        <mu2>100000</mu2>
        <kp>100000000.0</kp>
        <kd>1.0</kd>
    </gazebo>
    <joint name="gripper_finger1_finger_joint" type="fixed">
        <parent link="gripper_finger1_knuckle_link" />
        <child link="gripper_finger1_finger_link" />
        <origin rpy="0 0 0" xyz="-0.00408552455 -0.03148604435 0.0" />
    </joint>
    <joint name="gripper_finger2_finger_joint" type="fixed">
        <parent link="gripper_finger2_knuckle_link" />
        <child link="gripper_finger2_finger_link" />
        <origin rpy="0 0 0" xyz="-0.00408552455 -0.03148604435 0.0" />
    </joint>
    <link name="gripper_finger1_finger_link">
        <visual>
            <geometry>
                <mesh filename="package://ur_gazebo/mesh/visual/robotiq_85_finger_link.dae" />
            </geometry>
        </visual>
        <collision>
            <geometry>
                <mesh filename="package://ur_gazebo/mesh/collision/robotiq_85_finger_link.stl" />
            </geometry>
        </collision>
        <inertial>
            <mass value="0.027309" />
            <origin xyz="0.0 0.0 0.0" rpy="0 0 0" />
            <inertia ixx="0.000003" ixy="-0.000002" ixz="0.000000" iyx="-0.000002" iyy="0.000021" iyz="0.000000" izx="0.000000" izy="0.000000" izz="0.000020" />
        </inertial>
    </link>
    <gazebo reference="gripper_finger1_finger_link">
        <implicitSpringDamper>1</implicitSpringDamper>
        <mu1>100000</mu1>
        <mu2>100000</mu2>
        <kp>100000000.0</kp>
        <kd>1.0</kd>
    </gazebo>
    <link name="gripper_finger2_finger_link">
        <visual>
            <geometry>
                <mesh filename="package://ur_gazebo/mesh/visual/robotiq_85_finger_link.dae" />
            </geometry>
        </visual>
        <collision>
            <geometry>
                <mesh filename="package://ur_gazebo/mesh/collision/robotiq_85_finger_link.stl" />
            </geometry>
        </collision>
        <inertial>
            <mass value="0.027309" />
            <origin xyz="0.0 0.0 0.0" rpy="0 0 0" />
            <inertia ixx="0.000003" ixy="-0.000002" ixz="0.000000" iyx="-0.000002" iyy="0.000021" iyz="0.000000" izx="0.000000" izy="0.000000" izz="0.000020" />
        </inertial>
    </link>
    <gazebo reference="gripper_finger2_finger_link">
        <implicitSpringDamper>1</implicitSpringDamper>
        <mu1>100000</mu1>
        <mu2>100000</mu2>
        <kp>100000000.0</kp>
        <kd>1.0</kd>
    </gazebo>
    <joint name="gripper_finger1_inner_knuckle_joint" type="continuous">
        <parent link="gripper_base_link" />
        <child link="gripper_finger1_inner_knuckle_link" />
        <axis xyz="0 0 1" />
        <origin rpy="3.141592653589793 0.0 0.0" xyz="0.06142 0.0127 0" />
        <limit effort="0.1" lower="-3.14" upper="3.14" velocity="100.0" />
        <mimic joint="gripper_finger1_joint" offset="0" />
    </joint>
    <joint name="gripper_finger2_inner_knuckle_joint" type="continuous">
        <parent link="gripper_base_link" />
        <child link="gripper_finger2_inner_knuckle_link" />
        <axis xyz="0 0 1" />
        <origin rpy="0 0 0" xyz="0.06142 -0.0127 0" />
        <limit effort="0.1" lower="-3.14" upper="3.14" velocity="100.0" />
        <mimic joint="gripper_finger1_joint" offset="0" />
    </joint>
    <link name="gripper_finger1_inner_knuckle_link">
        <visual>
            <geometry>
                <mesh filename="package://ur_gazebo/mesh/visual/robotiq_85_inner_knuckle_link.dae" />
            </geometry>
        </visual>
        <collision>
            <geometry>
                <mesh filename="package://ur_gazebo/mesh/collision/robotiq_85_inner_knuckle_link.stl" />
            </geometry>
        </collision>
        <inertial>
            <mass value="0.029951" />
            <origin xyz="0.0 0.0 0.0" rpy="0 0 0" />
            <inertia ixx="0.000039" ixy="0.000000" ixz="0.000000" iyx="0.000000" iyy="0.000005" iyz="0.000000" izx="0.000000" izy="0.000000" izz="0.000035" />
        </inertial>
    </link>
    <gazebo reference="gripper_finger1_inner_knuckle_link">
        <implicitSpringDamper>1</implicitSpringDamper>
        <mu1>100000</mu1>
        <mu2>100000</mu2>
        <kp>100000000.0</kp>
        <kd>1.0</kd>
    </gazebo>
    <link name="gripper_finger2_inner_knuckle_link">
        <visual>
            <geometry>
                <mesh filename="package://ur_gazebo/mesh/visual/robotiq_85_inner_knuckle_link.dae" />
            </geometry>
        </visual>
        <collision>
            <geometry>
                <mesh filename="package://ur_gazebo/mesh/collision/robotiq_85_inner_knuckle_link.stl" />
            </geometry>
        </collision>
        <inertial>
            <mass value="0.029951" />
            <origin xyz="0.0 0.0 0.0" rpy="0 0 0" />
            <inertia ixx="0.000039" ixy="0.000000" ixz="0.000000" iyx="0.000000" iyy="0.000005" iyz="0.000000" izx="0.000000" izy="0.000000" izz="0.000035" />
        </inertial>
    </link>
    <gazebo reference="gripper_finger2_inner_knuckle_link">
        <implicitSpringDamper>1</implicitSpringDamper>
        <mu1>100000</mu1>
        <mu2>100000</mu2>
        <kp>100000000.0</kp>
        <kd>1.0</kd>
    </gazebo>
    <joint name="gripper_finger1_finger_tip_joint" type="continuous">
        <parent link="gripper_finger1_inner_knuckle_link" />
        <child link="gripper_finger1_finger_tip_link" />
        <axis xyz="0 0 1" />
        <origin rpy="0.0 0.0 0.0" xyz="0.04303959807 -0.03759940821 0.0" />
        <limit effort="0.1" lower="-3.14" upper="3.14" velocity="100.0" />
        <mimic joint="gripper_finger1_joint" multiplier="-1" />
    </joint>
    <joint name="gripper_finger2_finger_tip_joint" type="continuous">
        <parent link="gripper_finger2_inner_knuckle_link" />
        <child link="gripper_finger2_finger_tip_link" />
        <axis xyz="0 0 1" />
        <origin rpy="0.0 0.0 0.0" xyz="0.04303959807 -0.03759940821  0.0" />
        <limit effort="0.1" lower="-3.14" upper="3.14" velocity="100.0" />
        <mimic joint="gripper_finger1_joint" multiplier="-1" />
    </joint>
    <link name="gripper_finger1_finger_tip_link">
        <visual>
            <geometry>
                <mesh filename="package://ur_gazebo/mesh/visual/robotiq_85_finger_tip_link.dae" />
            </geometry>
        </visual>
        <collision>
            <geometry>
                <mesh filename="package://ur_gazebo/mesh/collision/robotiq_85_finger_tip_link.stl" />
            </geometry>
        </collision>
        <inertial>
            <mass value="0.019555" />
            <origin xyz="0.0 0.0 0.0" rpy="0 0 0" />
            <inertia ixx="0.000002" ixy="0.000000" ixz="0.000000" iyx="0.000000" iyy="0.000005" iyz="0.000000" izx="0.000000" izy="0.000000" izz="0.000006" />
        </inertial>
    </link>
    <gazebo reference="gripper_finger1_finger_tip_link">
        <implicitSpringDamper>1</implicitSpringDamper>
        <mu1>100000</mu1>
        <mu2>100000</mu2>
        <kp>100000000.0</kp>
        <kd>1.0</kd>
    </gazebo>
    <link name="gripper_finger2_finger_tip_link">
        <visual>
            <geometry>
                <mesh filename="package://ur_gazebo/mesh/visual/robotiq_85_finger_tip_link.dae" />
            </geometry>
        </visual>
        <collision>
            <geometry>
                <mesh filename="package://ur_gazebo/mesh/collision/robotiq_85_finger_tip_link.stl" />
            </geometry>
        </collision>
        <inertial>
            <mass value="0.019555" />
            <origin xyz="0.0 0.0 0.0" rpy="0 0 0" />
            <inertia ixx="0.000002" ixy="0.000000" ixz="0.000000" iyx="0.000000" iyy="0.000005" iyz="0.000000" izx="0.000000" izy="0.000000" izz="0.000006" />
        </inertial>
    </link>
    <gazebo reference="gripper_finger2_finger_tip_link">
        <implicitSpringDamper>1</implicitSpringDamper>
        <mu1>100000</mu1>
        <mu2>100000</mu2>
        <kp>100000000.0</kp>
        <kd>1.0</kd>
    </gazebo>
    <transmission name="gripper_finger1_trans">
        <type>transmission_interface/SimpleTransmission</type>
        <joint name="gripper_finger1_joint">
            <hardwareInterface>hardware_interface/PositionJointInterface</hardwareInterface>
        </joint>
        <actuator name="gripper_finger1_motor">
            <mechanicalReduction>1</mechanicalReduction>
            <hardwareInterface>hardware_interface/PositionJointInterface</hardwareInterface>
        </actuator>
    </transmission>
    <gazebo>
        <!-- loading plugin: mimic joints works in gazebo now -->
        <plugin filename="libroboticsgroup_gazebo_mimic_joint_plugin.so" name="mimic_robotiq_85_1">
            <joint>gripper_finger1_joint</joint>
            <mimicJoint>gripper_finger2_joint</mimicJoint>
            <!--multiplier>1.0</multiplier>
                <offset>0.0</offset-->
        </plugin>
        <plugin filename="libroboticsgroup_gazebo_mimic_joint_plugin.so" name="mimic_robotiq_85_2">
            <joint>gripper_finger1_joint</joint>
            <mimicJoint>gripper_finger2_inner_knuckle_joint</mimicJoint>
            <!--multiplier>1.0</multiplier>
                <offset>0.0</offset-->
        </plugin>
        <plugin filename="libroboticsgroup_gazebo_mimic_joint_plugin.so" name="mimic_robotiq_85_3">
            <joint>gripper_finger1_joint</joint>
            <mimicJoint>gripper_finger1_inner_knuckle_joint</mimicJoint>
            <!--multiplier>1.0</multiplier>
                <offset>0.0</offset-->
        </plugin>
        <plugin filename="libroboticsgroup_gazebo_mimic_joint_plugin.so" name="mimic_robotiq_85_4">
            <joint>gripper_finger1_joint</joint>
            <mimicJoint>gripper_finger1_finger_tip_joint</mimicJoint>
            <multiplier>-1.0</multiplier>
            <offset>0.0</offset>
        </plugin>
        <plugin filename="libroboticsgroup_gazebo_mimic_joint_plugin.so" name="mimic_robotiq_85_5">
            <joint>gripper_finger1_joint</joint>
            <mimicJoint>gripper_finger2_finger_tip_joint</mimicJoint>
            <multiplier>-1.0</multiplier>
            <offset>0.0</offset>
        </plugin>
    </gazebo>
    <transmission name="trans_gripper_finger2_joint">
        <type>transmission_interface/SimpleTransmission</type>
        <joint name="gripper_finger2_joint">
            <hardwareInterface>hardware_interface/EffortJointInterface</hardwareInterface>
        </joint>
        <actuator name="gripper_finger2_joint_motor">
            <hardwareInterface>hardware_interface/EffortJointInterface</hardwareInterface>
            <mechanicalReduction>1</mechanicalReduction>
        </actuator>
    </transmission>
    <transmission name="trans_gripper_finger1_inner_knuckle_joint">
        <type>transmission_interface/SimpleTransmission</type>
        <joint name="gripper_finger1_inner_knuckle_joint">
            <hardwareInterface>hardware_interface/EffortJointInterface</hardwareInterface>
        </joint>
        <actuator name="gripper_finger1_inner_knuckle_joint_motor">
            <hardwareInterface>hardware_interface/EffortJointInterface</hardwareInterface>
            <mechanicalReduction>1</mechanicalReduction>
        </actuator>
    </transmission>
    <transmission name="trans_gripper_finger2_inner_knuckle_joint">
        <type>transmission_interface/SimpleTransmission</type>
        <joint name="gripper_finger2_inner_knuckle_joint">
            <hardwareInterface>hardware_interface/EffortJointInterface</hardwareInterface>
        </joint>
        <actuator name="gripper_finger2_inner_knuckle_joint_motor">
            <hardwareInterface>hardware_interface/EffortJointInterface</hardwareInterface>
            <mechanicalReduction>1</mechanicalReduction>
        </actuator>
    </transmission>
    <transmission name="trans_gripper_finger1_finger_tip_joint">
        <type>transmission_interface/SimpleTransmission</type>
        <joint name="gripper_finger1_finger_tip_joint">
            <hardwareInterface>hardware_interface/EffortJointInterface</hardwareInterface>
        </joint>
        <actuator name="gripper_finger1_finger_tip_joint_motor">
            <hardwareInterface>hardware_interface/EffortJointInterface</hardwareInterface>
            <mechanicalReduction>1</mechanicalReduction>
        </actuator>
    </transmission>
    <transmission name="trans_gripper_finger2_finger_tip_joint">
        <type>transmission_interface/SimpleTransmission</type>
        <joint name="gripper_finger2_finger_tip_joint">
            <hardwareInterface>hardware_interface/EffortJointInterface</hardwareInterface>
        </joint>
        <actuator name="gripper_finger2_finger_tip_joint_motor">
            <hardwareInterface>hardware_interface/EffortJointInterface</hardwareInterface>
            <mechanicalReduction>1</mechanicalReduction>
        </actuator>
    </transmission>
</robot>

